Workbook

Sheet Instructions
A1: JE Vaccination Campaign - Daily Reporting Workbook
A2: जापानिज इन्सेफ्लाइटिस खोप अभियान - दैनिक प्रतिवेदन पुस्तिका
A4: How to use this file / प्रयोग विधि:
A5: 1. Each of the 15 sheet tabs below is one local level (palika), same as JE-083_84.xlsx.
A6: प्रत्येक ट्याब एउटा स्थानीय तह हो, JE-083_84.xlsx जस्तै।
A7: 2. Every sheet has a 'Campaign Total' table at the top, then one table per campaign day
A8: (Day 1 to Day 15) below it. Only type into the WHITE cells inside each day's table -
A9: the age 30-60 and age 60+ Female/Male counts for that day, for each ward.
A10: माथिको जम्मा तालिका र मुनि दिनको तालिकाहरू छन् - सेता कोष्ठमा मात्र त्यस दिनको संख्या लेख्नुहोस्।
A11: 3. Grey cells calculate themselves (Total, Grand Total, Progress %, and the Campaign
A12: Total table at the top). Do not type into grey cells.
A13: खरानी रङका कोष्ठले आफै गणना गर्छन् - त्यहाँ नलेख्नुहोस्।
... A20: Source of population / JE target figures: JE-083_84.xlsx (unchanged, kept alongside this file).

Sheet Mechinagar Municipality
A1: Mechinagar Municipality - Campaign Total (5-19 Oct 2026)
A2: Ward no. | B2: Total population | C2: JE target population | D2: Vaccinated | M2: Progress %
D3: Age 30-60 yrs | G3: Age 60 above | J3: Total | L3: Grand Total
D4: F | E4: M | F4: Total | G4: F | H4: M | I4: Total | J4: F | K4: M
A5: 1 | B5: 6478 | C5: 3109.44 | D5: =D26+D47+D68+D89+D110+D131+D152+D173+D194+D215+D236+D257+D278+D299+D320 | E5: =E26+E47+E68+E89+E110+E131+E152+E173+E194+E215+E236+E257+E278+E299+E320 | F5: =D5+E5 | G5: =G26+G47+G68+G89+G110+G131+G152+G173+G194+G215+G236+G257+G278+G299+G320 | H5: =H26+H47+H68+H89+H110+H131+H152+H173+H194+H215+H236+H257+H278+H299+H320 | I5: =G5+H5 | J5: =D5+G5 | K5: =E5+H5 | L5: =J5+K5 | M5: =IF(C5=0,0,L5/C5*100)
A6: 2 | B6: 6940 | C6: 3331.2 | D6: =D27+D48+D69+D90+D111+D132+D153+D174+D195+D216+D237+D258+D279+D300+D321 | E6: =E27+E48+E69+E90+E111+E132+E153+E174+E195+E216+E237+E258+E279+E300+E321 | F6: =D6+E6 | G6: =G27+G48+G69+G90+G111+G132+G153+G174+G195+G216+G237+G258+G279+G300+G321 | H6: =H27+H48+H69+H90+H111+H132+H153+H174+H195+H216+H237+H258+H279+H300+H321 | I6: =G6+H6 | J6: =D6+G6 | K6: =E6+H6 | L6: =J6+K6 | M6: =IF(C6=0,0,L6/C6*100)
A7: 3 | B7: 7375 | C7: 3540 | D7: =D28+D49+D70+D91+D112+D133+D154+D175+D196+D217+D238+D259+D280+D301+D322 | E7: =E28+E49+E70+E91+E112+E133+E154+E175+E196+E217+E238+E259+E280+E301+E322 | F7: =D7+E7 | G7: =G28+G49+G70+G91+G112+G133+G154+G175+G196+G217+G238+G259+G280+G301+G322 | H7: =H28+H49+H70+H91+H112+H133+H154+H175+H196+H217+H238+H259+H280+H301+H322 | I7: =G7+H7 | J7: =D7+G7 | K7: =E7+H7 | L7: =J7+K7 | M7: =IF(C7=0,0,L7/C7*100)
A8: 4 | B8: 5531 | C8: 2654.88 | D8: =D29+D50+D71+D92+D113+D134+D155+D176+D197+D218+D239+D260+D281+D302+D323 | E8: =E29+E50+E71+E92+E113+E134+E155+E176+E197+E218+E239+E260+E281+E302+E323 | F8: =D8+E8 | G8: =G29+G50+G71+G92+G113+G134+G155+G176+G197+G218+G239+G260+G281+G302+G323 | H8: =H29+H50+H71+H92+H113+H134+H155+H176+H197+H218+H239+H260+H281+H302+H323 | I8: =G8+H8 | J8: =D8+G8 | K8: =E8+H8 | L8: =J8+K8 | M8: =IF(C8=0,0,L8/C8*100)
A9: 5 | B9: 5457 | C9: 2619.36 | D9: =D30+D51+D72+D93+D114+D135+D156+D177+D198+D219+D240+D261+D282+D303+D324 | E9: =E30+E51+E72+E93+E114+E135+E156+E177+E198+E219+E240+E261+E282+E303+E324 | F9: =D9+E9 | G9: =G30+G51+G72+G93+G114+G135+G156+G177+G198+G219+G240+G261+G282+G303+G324 | H9: =H30+H51+H72+H93+H114+H135+H156+H177+H198+H219+H240+H261+H282+H303+H324 | I9: =G9+H9 | J9: =D9+G9 | K9: =E9+H9 | L9: =J9+K9 | M9: =IF(C9=0,0,L9/C9*100)
A10: 6 | B10: 16161 | C10: 7757.28 | D10: =D31+D52+D73+D94+D115+D136+D157+D178+D199+D220+D241+D262+D283+D304+D325 | E10: =E31+E52+E73+E94+E115+E136+E157+E178+E199+E220+E241+E262+E283+E304+E325 | F10: =D10+E10 | G10: =G31+G52+G73+G94+G115+G136+G157+G178+G199+G220+G241+G262+G283+G304+G325 | H10: =H31+H52+H73+H94+H115+H136+H157+H178+H199+H220+H241+H262+H283+H304+H325 | I10: =G10+H10 | J10: =D10+G10 | K10: =E10+H10 | L10: =J10+K10 | M10: =IF(C10=0,0,L10/C10*100)
A11: 7 | B11: 13537 | C11: 6497.76 | D11: =D32+D53+D74+D95+D116+D137+D158+D179+D200+D221+D242+D263+D284+D305+D326 | E11: =E32+E53+E74+E95+E116+E137+E158+E179+E200+E221+E242+E263+E284+E305+E326 | F11: =D11+E11 | G11: =G32+G53+G74+G95+G116+G137+G158+G179+G200+G221+G242+G263+G284+G305+G326 | H11: =H32+H53+H74+H95+H116+H137+H158+H179+H200+H221+H242+H263+H284+H305+H326 | I11: =G11+H11 | J11: =D11+G11 | K11: =E11+H11 | L11: =J11+K11 | M11: =IF(C11=0,0,L11/C11*100)
A12: 8 | B12: 8527 | C12: 4092.96 | D12: =D33+D54+D75+D96+D117+D138+D159+D180+D201+D222+D243+D264+D285+D306+D327 | E12: =E33+E54+E75+E96+E117+E138+E159+E180+E201+E222+E243+E264+E285+E306+E327 | F12: =D12+E12 | G12: =G33+G54+G75+G96+G117+G138+G159+G180+G201+G222+G243+G264+G285+G306+G327 | H12: =H33+H54+H75+H96+H117+H138+H159+H180+H201+H222+H243+H264+H285+H306+H327 | I12: =G12+H12 | J12: =D12+G12 | K12: =E12+H12 | L12: =J12+K12 | M12: =IF(C12=0,0,L12/C12*100)
A13: 9 | B13: 12286 | C13: 5897.28 | D13: =D34+D55+D76+D97+D118+D139+D160+D181+D202+D223+D244+D265+D286+D307+D328 | E13: =E34+E55+E76+E97+E118+E139+E160+E181+E202+E223+E244+E265+E286+E307+E328 | F13: =D13+E13 | G13: =G34+G55+G76+G97+G118+G139+G160+G181+G202+G223+G244+G265+G286+G307+G328 | H13: =H34+H55+H76+H97+H118+H139+H160+H181+H202+H223+H244+H265+H286+H307+H328 | I13: =G13+H13 | J13: =D13+G13 | K13: =E13+H13 | L13: =J13+K13 | M13: =IF(C13=0,0,L13/C13*100)
A14: 10 | B14: 15923 | C14: 7643.04 | D14: =D35+D56+D77+D98+D119+D140+D161+D182+D203+D224+D245+D266+D287+D308+D329 | E14: =E35+E56+E77+E98+E119+E140+E161+E182+E203+E224+E245+E266+E287+E308+E329 | F14: =D14+E14 | G14: =G35+G56+G77+G98+G119+G140+G161+G182+G203+G224+G245+G266+G287+G308+G329 | H14: =H35+H56+H77+H98+H119+H140+H161+H182+H203+H224+H245+H266+H287+H308+H329 | I14: =G14+H14 | J14: =D14+G14 | K14: =E14+H14 | L14: =J14+K14 | M14: =IF(C14=0,0,L14/C14*100)
A15: 11 | B15: 6760 | C15: 3244.8 | D15: =D36+D57+D78+D99+D120+D141+D162+D183+D204+D225+D246+D267+D288+D309+D330 | E15: =E36+E57+E78+E99+E120+E141+E162+E183+E204+E225+E246+E267+E288+E309+E330 | F15: =D15+E15 | G15: =G36+G57+G78+G99+G120+G141+G162+G183+G204+G225+G246+G267+G288+G309+G330 | H15: =H36+H57+H78+H99+H120+H141+H162+H183+H204+H225+H246+H267+H288+H309+H330 | I15: =G15+H15 | J15: =D15+G15 | K15: =E15+H15 | L15: =J15+K15 | M15: =IF(C15=0,0,L15/C15*100)
A16: 12 | B16: 8356 | C16: 4010.88 | D16: =D37+D58+D79+D100+D121+D142+D163+D184+D205+D226+D247+D268+D289+D310+D331 | E16: =E37+E58+E79+E100+E121+E142+E163+E184+E205+E226+E247+E268+E289+E310+E331 | F16: =D16+E16 | G16: =G37+G58+G79+G100+G121+G142+G163+G184+G205+G226+G247+G268+G289+G310+G331 | H16: =H37+H58+H79+H100+H121+H142+H163+H184+H205+H226+H247+H268+H289+H310+H331 | I16: =G16+H16 | J16: =D16+G16 | K16: =E16+H16 | L16: =J16+K16 | M16: =IF(C16=0,0,L16/C16*100)
... A19: 15 | B19: 8487 | C19: 4073.76 | D19: =D40+D61+D82+D103+D124+D145+D166+D187+D208+D229+D250+D271+D292+D313+D334 | E19: =E40+E61+E82+E103+E124+E145+E166+E187+E208+E229+E250+E271+E292+E313+E334 | F19: =D19+E19 | G19: =G40+G61+G82+G103+G124+G145+G166+G187+G208+G229+G250+G271+G292+G313+G334 | H19: =H40+H61+H82+H103+H124+H145+H166+H187+H208+H229+H250+H271+H292+H313+H334 | I19: =G19+H19 | J19: =D19+G19 | K19: =E19+H19 | L19: =J19+K19 | M19: =IF(C19=0,0,L19/C19*100)
A20: Total | B20: =SUM(B5:B19) | C20: =SUM(C5:C19) | D20: =SUM(D5:D19) | E20: =SUM(E5:E19) | F20: =D20+E20 | G20: =SUM(G5:G19) | H20: =SUM(H5:H19) | I20: =G20+H20 | J20: =D20+G20 | K20: =E20+H20 | L20: =J20+K20 | M20: =IF(C20=0,0,L20/C20*100)
A22: Day 1 - 2026-10-05 (Mon 19 Aswin 2083)
A23: Ward no. | B23: Total population | C23: JE target population | D23: Vaccinated | M23: Progress %
D24: Age 30-60 yrs | G24: Age 60 above | J24: Total | L24: Grand Total
D25: F | E25: M | F25: Total | G25: F | H25: M | I25: Total | J25: F | K25: M
A26: 1 | B26: =B5 | C26: =C5 | F26: =D26+E26 | I26: =G26+H26 | J26: =D26+G26 | K26: =E26+H26 | L26: =J26+K26 | M26: =IF(C26=0,0,L26/C26*100)
A27: 2 | B27: =B6 | C27: =C6 | F27: =D27+E27 | I27: =G27+H27 | J27: =D27+G27 | K27: =E27+H27 | L27: =J27+K27 | M27: =IF(C27=0,0,L27/C27*100)
A28: 3 | B28: =B7 | C28: =C7 | F28: =D28+E28 | I28: =G28+H28 | J28: =D28+G28 | K28: =E28+H28 | L28: =J28+K28 | M28: =IF(C28=0,0,L28/C28*100)
A29: 4 | B29: =B8 | C29: =C8 | F29: =D29+E29 | I29: =G29+H29 | J29: =D29+G29 | K29: =E29+H29 | L29: =J29+K29 | M29: =IF(C29=0,0,L29/C29*100)
A30: 5 | B30: =B9 | C30: =C9 | F30: =D30+E30 | I30: =G30+H30 | J30: =D30+G30 | K30: =E30+H30 | L30: =J30+K30 | M30: =IF(C30=0,0,L30/C30*100)
A31: 6 | B31: =B10 | C31: =C10 | F31: =D31+E31 | I31: =G31+H31 | J31: =D31+G31 | K31: =E31+H31 | L31: =J31+K31 | M31: =IF(C31=0,0,L31/C31*100)
A32: 7 | B32: =B11 | C32: =C11 | F32: =D32+E32 | I32: =G32+H32 | J32: =D32+G32 | K32: =E32+H32 | L32: =J32+K32 | M32: =IF(C32=0,0,L32/C32*100)
A33: 8 | B33: =B12 | C33: =C12 | F33: =D33+E33 | I33: =G33+H33 | J33: =D33+G33 | K33: =E33+H33 | L33: =J33+K33 | M33: =IF(C33=0,0,L33/C33*100)
A34: 9 | B34: =B13 | C34: =C13 | F34: =D34+E34 | I34: =G34+H34 | J34: =D34+G34 | K34: =E34+H34 | L34: =J34+K34 | M34: =IF(C34=0,0,L34/C34*100)
A35: 10 | B35: =B14 | C35: =C14 | F35: =D35+E35 | I35: =G35+H35 | J35: =D35+G35 | K35: =E35+H35 | L35: =J35+K35 | M35: =IF(C35=0,0,L35/C35*100)
A36: 11 | B36: =B15 | C36: =C15 | F36: =D36+E36 | I36: =G36+H36 | J36: =D36+G36 | K36: =E36+H36 | L36: =J36+K36 | M36: =IF(C36=0,0,L36/C36*100)
A37: 12 | B37: =B16 | C37: =C16 | F37: =D37+E37 | I37: =G37+H37 | J37: =D37+G37 | K37: =E37+H37 | L37: =J37+K37 | M37: =IF(C37=0,0,L37/C37*100)
... A40: 15 | B40: =B19 | C40: =C19 | F40: =D40+E40 | I40: =G40+H40 | J40: =D40+G40 | K40: =E40+H40 | L40: =J40+K40 | M40: =IF(C40=0,0,L40/C40*100)
A41: Total | B41: =SUM(B26:B40) | C41: =SUM(C26:C40) | D41: =SUM(D26:D40) | E41: =SUM(E26:E40) | F41: =D41+E41 | G41: =SUM(G26:G40) | H41: =SUM(H26:H40) | I41: =G41+H41 | J41: =D41+G41 | K41: =E41+H41 | L41: =J41+K41 | M41: =IF(C41=0,0,L41/C41*100)
A43: Day 2 - 2026-10-06 (Tue 20 Aswin 2083)
A44: Ward no. | B44: Total population | C44: JE target population | D44: Vaccinated | M44: Progress %
D45: Age 30-60 yrs | G45: Age 60 above | J45: Total | L45: Grand Total
D46: F | E46: M | F46: Total | G46: F | H46: M | I46: Total | J46: F | K46: M
...

Sheet Buddhashanti Gaunpalika
A1: Buddhashanti Gaunpalika - Campaign Total (5-19 Oct 2026)
A2: Ward no. | B2: Total population | C2: JE target population | D2: Vaccinated | M2: Progress %
D3: Age 30-60 yrs | G3: Age 60 above | J3: Total | L3: Grand Total
D4: F | E4: M | F4: Total | G4: F | H4: M | I4: Total | J4: F | K4: M
A5: 1 | B5: 10670 | C5: 5121.6 | D5: =D18+D31+D44+D57+D70+D83+D96+D109+D122+D135+D148+D161+D174+D187+D200 | E5: =E18+E31+E44+E57+E70+E83+E96+E109+E122+E135+E148+E161+E174+E187+E200 | F5: =D5+E5 | G5: =G18+G31+G44+G57+G70+G83+G96+G109+G122+G135+G148+G161+G174+G187+G200 | H5: =H18+H31+H44+H57+H70+H83+H96+H109+H122+H135+H148+H161+H174+H187+H200 | I5: =G5+H5 | J5: =D5+G5 | K5: =E5+H5 | L5: =J5+K5 | M5: =IF(C5=0,0,L5/C5*100)
A6: 2 | B6: 9393 | C6: 4508.64 | D6: =D19+D32+D45+D58+D71+D84+D97+D110+D123+D136+D149+D162+D175+D188+D201 | E6: =E19+E32+E45+E58+E71+E84+E97+E110+E123+E136+E149+E162+E175+E188+E201 | F6: =D6+E6 | G6: =G19+G32+G45+G58+G71+G84+G97+G110+G123+G136+G149+G162+G175+G188+G201 | H6: =H19+H32+H45+H58+H71+H84+H97+H110+H123+H136+H149+H162+H175+H188+H201 | I6: =G6+H6 | J6: =D6+G6 | K6: =E6+H6 | L6: =J6+K6 | M6: =IF(C6=0,0,L6/C6*100)
A7: 3 | B7: 12660 | C7: 6076.8 | D7: =D20+D33+D46+D59+D72+D85+D98+D111+D124+D137+D150+D163+D176+D189+D202 | E7: =E20+E33+E46+E59+E72+E85+E98+E111+E124+E137+E150+E163+E176+E189+E202 | F7: =D7+E7 | G7: =G20+G33+G46+G59+G72+G85+G98+G111+G124+G137+G150+G163+G176+G189+G202 | H7: =H20+H33+H46+H59+H72+H85+H98+H111+H124+H137+H150+H163+H176+H189+H202 | I7: =G7+H7 | J7: =D7+G7 | K7: =E7+H7 | L7: =J7+K7 | M7: =IF(C7=0,0,L7/C7*100)
A8: 4 | B8: 12054 | C8: 5785.92 | D8: =D21+D34+D47+D60+D73+D86+D99+D112+D125+D138+D151+D164+D177+D190+D203 | E8: =E21+E34+E47+E60+E73+E86+E99+E112+E125+E138+E151+E164+E177+E190+E203 | F8: =D8+E8 | G8: =G21+G34+G47+G60+G73+G86+G99+G112+G125+G138+G151+G164+G177+G190+G203 | H8: =H21+H34+H47+H60+H73+H86+H99+H112+H125+H138+H151+H164+H177+H190+H203 | I8: =G8+H8 | J8: =D8+G8 | K8: =E8+H8 | L8: =J8+K8 | M8: =IF(C8=0,0,L8/C8*100)
A9: 5 | B9: 4123 | C9: 1979.04 | D9: =D22+D35+D48+D61+D74+D87+D100+D113+D126+D139+D152+D165+D178+D191+D204 | E9: =E22+E35+E48+E61+E74+E87+E100+E113+E126+E139+E152+E165+E178+E191+E204 | F9: =D9+E9 | G9: =G22+G35+G48+G61+G74+G87+G100+G113+G126+G139+G152+G165+G178+G191+G204 | H9: =H22+H35+H48+H61+H74+H87+H100+H113+H126+H139+H152+H165+H178+H191+H204 | I9: =G9+H9 | J9: =D9+G9 | K9: =E9+H9 | L9: =J9+K9 | M9: =IF(C9=0,0,L9/C9*100)
A10: 6 | B10: 3304 | C10: 1585.92 | D10: =D23+D36+D49+D62+D75+D88+D101+D114+D127+D140+D153+D166+D179+D192+D205 | E10: =E23+E36+E49+E62+E75+E88+E101+E114+E127+E140+E153+E166+E179+E192+E205 | F10: =D10+E10 | G10: =G23+G36+G49+G62+G75+G88+G101+G114+G127+G140+G153+G166+G179+G192+G205 | H10: =H23+H36+H49+H62+H75+H88+H101+H114+H127+H140+H153+H166+H179+H192+H205 | I10: =G10+H10 | J10: =D10+G10 | K10: =E10+H10 | L10: =J10+K10 | M10: =IF(C10=0,0,L10/C10*100)
A11: 7 | B11: 2349 | C11: 1127.52 | D11: =D24+D37+D50+D63+D76+D89+D102+D115+D128+D141+D154+D167+D180+D193+D206 | E11: =E24+E37+E50+E63+E76+E89+E102+E115+E128+E141+E154+E167+E180+E193+E206 | F11: =D11+E11 | G11: =G24+G37+G50+G63+G76+G89+G102+G115+G128+G141+G154+G167+G180+G193+G206 | H11: =H24+H37+H50+H63+H76+H89+H102+H115+H128+H141+H154+H167+H180+H193+H206 | I11: =G11+H11 | J11: =D11+G11 | K11: =E11+H11 | L11: =J11+K11 | M11: =IF(C11=0,0,L11/C11*100)
A12: Total | B12: =SUM(B5:B11) | C12: =SUM(C5:C11) | D12: =SUM(D5:D11) | E12: =SUM(E5:E11) | F12: =D12+E12 | G12: =SUM(G5:G11) | H12: =SUM(H5:H11) | I12: =G12+H12 | J12: =D12+G12 | K12: =E12+H12 | L12: =J12+K12 | M12: =IF(C12=0,0,L12/C12*100)
A14: Day 1 - 2026-10-05 (Mon 19 Aswin 2083)
A15: Ward no. | B15: Total population | C15: JE target population | D15: Vaccinated | M15: Progress %
D16: Age 30-60 yrs | G16: Age 60 above | J16: Total | L16: Grand Total
D17: F | E17: M | F17: Total | G17: F | H17: M | I17: Total | J17: F | K17: M
A18: 1 | B18: =B5 | C18: =C5 | F18: =D18+E18 | I18: =G18+H18 | J18: =D18+G18 | K18: =E18+H18 | L18: =J18+K18 | M18: =IF(C18=0,0,L18/C18*100)
A19: 2 | B19: =B6 | C19: =C6 | F19: =D19+E19 | I19: =G19+H19 | J19: =D19+G19 | K19: =E19+H19 | L19: =J19+K19 | M19: =IF(C19=0,0,L19/C19*100)
A20: 3 | B20: =B7 | C20: =C7 | F20: =D20+E20 | I20: =G20+H20 | J20: =D20+G20 | K20: =E20+H20 | L20: =J20+K20 | M20: =IF(C20=0,0,L20/C20*100)
A21: 4 | B21: =B8 | C21: =C8 | F21: =D21+E21 | I21: =G21+H21 | J21: =D21+G21 | K21: =E21+H21 | L21: =J21+K21 | M21: =IF(C21=0,0,L21/C21*100)
A22: 5 | B22: =B9 | C22: =C9 | F22: =D22+E22 | I22: =G22+H22 | J22: =D22+G22 | K22: =E22+H22 | L22: =J22+K22 | M22: =IF(C22=0,0,L22/C22*100)
A23: 6 | B23: =B10 | C23: =C10 | F23: =D23+E23 | I23: =G23+H23 | J23: =D23+G23 | K23: =E23+H23 | L23: =J23+K23 | M23: =IF(C23=0,0,L23/C23*100)
A24: 7 | B24: =B11 | C24: =C11 | F24: =D24+E24 | I24: =G24+H24 | J24: =D24+G24 | K24: =E24+H24 | L24: =J24+K24 | M24: =IF(C24=0,0,L24/C24*100)
A25: Total | B25: =SUM(B18:B24) | C25: =SUM(C18:C24) | D25: =SUM(D18:D24) | E25: =SUM(E18:E24) | F25: =D25+E25 | G25: =SUM(G18:G24) | H25: =SUM(H18:H24) | I25: =G25+H25 | J25: =D25+G25 | K25: =E25+H25 | L25: =J25+K25 | M25: =IF(C25=0,0,L25/C25*100)
A27: Day 2 - 2026-10-06 (Tue 20 Aswin 2083)
A28: Ward no. | B28: Total population | C28: JE target population | D28: Vaccinated | M28: Progress %
D29: Age 30-60 yrs | G29: Age 60 above | J29: Total | L29: Grand Total
D30: F | E30: M | F30: Total | G30: F | H30: M | I30: Total | J30: F | K30: M
A31: 1 | B31: =B5 | C31: =C5 | F31: =D31+E31 | I31: =G31+H31 | J31: =D31+G31 | K31: =E31+H31 | L31: =J31+K31 | M31: =IF(C31=0,0,L31/C31*100)
A32: 2 | B32: =B6 | C32: =C6 | F32: =D32+E32 | I32: =G32+H32 | J32: =D32+G32 | K32: =E32+H32 | L32: =J32+K32 | M32: =IF(C32=0,0,L32/C32*100)
A33: 3 | B33: =B7 | C33: =C7 | F33: =D33+E33 | I33: =G33+H33 | J33: =D33+G33 | K33: =E33+H33 | L33: =J33+K33 | M33: =IF(C33=0,0,L33/C33*100)
A34: 4 | B34: =B8 | C34: =C8 | F34: =D34+E34 | I34: =G34+H34 | J34: =D34+G34 | K34: =E34+H34 | L34: =J34+K34 | M34: =IF(C34=0,0,L34/C34*100)
A35: 5 | B35: =B9 | C35: =C9 | F35: =D35+E35 | I35: =G35+H35 | J35: =D35+G35 | K35: =E35+H35 | L35: =J35+K35 | M35: =IF(C35=0,0,L35/C35*100)
A36: 6 | B36: =B10 | C36: =C10 | F36: =D36+E36 | I36: =G36+H36 | J36: =D36+G36 | K36: =E36+H36 | L36: =J36+K36 | M36: =IF(C36=0,0,L36/C36*100)
A37: 7 | B37: =B11 | C37: =C11 | F37: =D37+E37 | I37: =G37+H37 | J37: =D37+G37 | K37: =E37+H37 | L37: =J37+K37 | M37: =IF(C37=0,0,L37/C37*100)
A38: Total | B38: =SUM(B31:B37) | C38: =SUM(C31:C37) | D38: =SUM(D31:D37) | E38: =SUM(E31:E37) | F38: =D38+E38 | G38: =SUM(G31:G37) | H38: =SUM(H31:H37) | I38: =G38+H38 | J38: =D38+G38 | K38: =E38+H38 | L38: =J38+K38 | M38: =IF(C38=0,0,L38/C38*100)
A40: Day 3 - 2026-10-07 (Wed 21 Aswin 2083)
A41: Ward no. | B41: Total population | C41: JE target population | D41: Vaccinated | M41: Progress %
D42: Age 30-60 yrs | G42: Age 60 above | J42: Total | L42: Grand Total
D43: F | E43: M | F43: Total | G43: F | H43: M | I43: Total | J43: F | K43: M
...

Sheet Arjundhara Municipality
A1: Arjundhara Municipality - Campaign Total (5-19 Oct 2026)
A2: Ward no. | B2: Total population | C2: JE target population | D2: Vaccinated | M2: Progress %
D3: Age 30-60 yrs | G3: Age 60 above | J3: Total | L3: Grand Total
D4: F | E4: M | F4: Total | G4: F | H4: M | I4: Total | J4: F | K4: M
A5: 1 | B5: 6994 | C5: 3357.12 | D5: =D22+D39+D56+D73+D90+D107+D124+D141+D158+D175+D192+D209+D226+D243+D260 | E5: =E22+E39+E56+E73+E90+E107+E124+E141+E158+E175+E192+E209+E226+E243+E260 | F5: =D5+E5 | G5: =G22+G39+G56+G73+G90+G107+G124+G141+G158+G175+G192+G209+G226+G243+G260 | H5: =H22+H39+H56+H73+H90+H107+H124+H141+H158+H175+H192+H209+H226+H243+H260 | I5: =G5+H5 | J5: =D5+G5 | K5: =E5+H5 | L5: =J5+K5 | M5: =IF(C5=0,0,L5/C5*100)
A6: 2 | B6: 5836 | C6: 2801.28 | D6: =D23+D40+D57+D74+D91+D108+D125+D142+D159+D176+D193+D210+D227+D244+D261 | E6: =E23+E40+E57+E74+E91+E108+E125+E142+E159+E176+E193+E210+E227+E244+E261 | F6: =D6+E6 | G6: =G23+G40+G57+G74+G91+G108+G125+G142+G159+G176+G193+G210+G227+G244+G261 | H6: =H23+H40+H57+H74+H91+H108+H125+H142+H159+H176+H193+H210+H227+H244+H261 | I6: =G6+H6 | J6: =D6+G6 | K6: =E6+H6 | L6: =J6+K6 | M6: =IF(C6=0,0,L6/C6*100)
A7: 3 | B7: 7049 | C7: 3383.52 | D7: =D24+D41+D58+D75+D92+D109+D126+D143+D160+D177+D194+D211+D228+D245+D262 | E7: =E24+E41+E58+E75+E92+E109+E126+E143+E160+E177+E194+E211+E228+E245+E262 | F7: =D7+E7 | G7: =G24+G41+G58+G75+G92+G109+G126+G143+G160+G177+G194+G211+G228+G245+G262 | H7: =H24+H41+H58+H75+H92+H109+H126+H143+H160+H177+H194+H211+H228+H245+H262 | I7: =G7+H7 | J7: =D7+G7 | K7: =E7+H7 | L7: =J7+K7 | M7: =IF(C7=0,0,L7/C7*100)
A8: 4 | B8: 6745 | C8: 3237.6 | D8: =D25+D42+D59+D76+D93+D110+D127+D144+D161+D178+D195+D212+D229+D246+D263 | E8: =E25+E42+E59+E76+E93+E110+E127+E144+E161+E178+E195+E212+E229+E246+E263 | F8: =D8+E8 | G8: =G25+G42+G59+G76+G93+G110+G127+G144+G161+G178+G195+G212+G229+G246+G263 | H8: =H25+H42+H59+H76+H93+H110+H127+H144+H161+H178+H195+H212+H229+H246+H263 | I8: =G8+H8 | J8: =D8+G8 | K8: =E8+H8 | L8: =J8+K8 | M8: =IF(C8=0,0,L8/C8*100)
A9: 5 | B9: 10360 | C9: 4972.8 | D9: =D26+D43+D60+D77+D94+D111+D128+D145+D162+D179+D196+D213+D230+D247+D264 | E9: =E26+E43+E60+E77+E94+E111+E128+E145+E162+E179+E196+E213+E230+E247+E264 | F9: =D9+E9 | G9: =G26+G43+G60+G77+G94+G111+G128+G145+G162+G179+G196+G213+G230+G247+G264 | H9: =H26+H43+H60+H77+H94+H111+H128+H145+H162+H179+H196+H213+H230+H247+H264 | I9: =G9+H9 | J9: =D9+G9 | K9: =E9+H9 | L9: =J9+K9 | M9: =IF(C9=0,0,L9/C9*100)
A10: 6 | B10: 12099 | C10: 5807.52 | D10: =D27+D44+D61+D78+D95+D112+D129+D146+D163+D180+D197+D214+D231+D248+D265 | E10: =E27+E44+E61+E78+E95+E112+E129+E146+E163+E180+E197+E214+E231+E248+E265 | F10: =D10+E10 | G10: =G27+G44+G61+G78+G95+G112+G129+G146+G163+G180+G197+G214+G231+G248+G265 | H10: =H27+H44+H61+H78+H95+H112+H129+H146+H163+H180+H197+H214+H231+H248+H265 | I10: =G10+H10 | J10: =D10+G10 | K10: =E10+H10 | L10: =J10+K10 | M10: =IF(C10=0,0,L10/C10*100)
A11: 7 | B11: 4939 | C11: 2370.72 | D11: =D28+D45+D62+D79+D96+D113+D130+D147+D164+D181+D198+D215+D232+D249+D266 | E11: =E28+E45+E62+E79+E96+E113+E130+E147+E164+E181+E198+E215+E232+E249+E266 | F11: =D11+E11 | G11: =G28+G45+G62+G79+G96+G113+G130+G147+G164+G181+G198+G215+G232+G249+G266 | H11: =H28+H45+H62+H79+H96+H113+H130+H147+H164+H181+H198+H215+H232+H249+H266 | I11: =G11+H11 | J11: =D11+G11 | K11: =E11+H11 | L11: =J11+K11 | M11: =IF(C11=0,0,L11/C11*100)
A12: 8 | B12: 6905 | C12: 3314.4 | D12: =D29+D46+D63+D80+D97+D114+D131+D148+D165+D182+D199+D216+D233+D250+D267 | E12: =E29+E46+E63+E80+E97+E114+E131+E148+E165+E182+E199+E216+E233+E250+E267 | F12: =D12+E12 | G12: =G29+G46+G63+G80+G97+G114+G131+G148+G165+G182+G199+G216+G233+G250+G267 | H12: =H29+H46+H63+H80+H97+H114+H131+H148+H165+H182+H199+H216+H233+H250+H267 | I12: =G12+H12 | J12: =D12+G12 | K12: =E12+H12 | L12: =J12+K12 | M12: =IF(C12=0,0,L12/C12*100)
A13: 9 | B13: 8301 | C13: 3984.48 | D13: =D30+D47+D64+D81+D98+D115+D132+D149+D166+D183+D200+D217+D234+D251+D268 | E13: =E30+E47+E64+E81+E98+E115+E132+E149+E166+E183+E200+E217+E234+E251+E268 | F13: =D13+E13 | G13: =G30+G47+G64+G81+G98+G115+G132+G149+G166+G183+G200+G217+G234+G251+G268 | H13: =H30+H47+H64+H81+H98+H115+H132+H149+H166+H183+H200+H217+H234+H251+H268 | I13: =G13+H13 | J13: =D13+G13 | K13: =E13+H13 | L13: =J13+K13 | M13: =IF(C13=0,0,L13/C13*100)
A14: 10 | B14: 7266 | C14: 3487.68 | D14: =D31+D48+D65+D82+D99+D116+D133+D150+D167+D184+D201+D218+D235+D252+D269 | E14: =E31+E48+E65+E82+E99+E116+E133+E150+E167+E184+E201+E218+E235+E252+E269 | F14: =D14+E14 | G14: =G31+G48+G65+G82+G99+G116+G133+G150+G167+G184+G201+G218+G235+G252+G269 | H14: =H31+H48+H65+H82+H99+H116+H133+H150+H167+H184+H201+H218+H235+H252+H269 | I14: =G14+H14 | J14: =D14+G14 | K14: =E14+H14 | L14: =J14+K14 | M14: =IF(C14=0,0,L14/C14*100)
A15: 11 | B15: 12394 | C15: 5949.12 | D15: =D32+D49+D66+D83+D100+D117+D134+D151+D168+D185+D202+D219+D236+D253+D270 | E15: =E32+E49+E66+E83+E100+E117+E134+E151+E168+E185+E202+E219+E236+E253+E270 | F15: =D15+E15 | G15: =G32+G49+G66+G83+G100+G117+G134+G151+G168+G185+G202+G219+G236+G253+G270 | H15: =H32+H49+H66+H83+H100+H117+H134+H151+H168+H185+H202+H219+H236+H253+H270 | I15: =G15+H15 | J15: =D15+G15 | K15: =E15+H15 | L15: =J15+K15 | M15: =IF(C15=0,0,L15/C15*100)
A16: Total | B16: =SUM(B5:B15) | C16: =SUM(C5:C15) | D16: =SUM(D5:D15) | E16: =SUM(E5:E15) | F16: =D16+E16 | G16: =SUM(G5:G15) | H16: =SUM(H5:H15) | I16: =G16+H16 | J16: =D16+G16 | K16: =E16+H16 | L16: =J16+K16 | M16: =IF(C16=0,0,L16/C16*100)
A18: Day 1 - 2026-10-05 (Mon 19 Aswin 2083)
A19: Ward no. | B19: Total population | C19: JE target population | D19: Vaccinated | M19: Progress %
D20: Age 30-60 yrs | G20: Age 60 above | J20: Total | L20: Grand Total
D21: F | E21: M | F21: Total | G21: F | H21: M | I21: Total | J21: F | K21: M
A22: 1 | B22: =B5 | C22: =C5 | F22: =D22+E22 | I22: =G22+H22 | J22: =D22+G22 | K22: =E22+H22 | L22: =J22+K22 | M22: =IF(C22=0,0,L22/C22*100)
A23: 2 | B23: =B6 | C23: =C6 | F23: =D23+E23 | I23: =G23+H23 | J23: =D23+G23 | K23: =E23+H23 | L23: =J23+K23 | M23: =IF(C23=0,0,L23/C23*100)
A24: 3 | B24: =B7 | C24: =C7 | F24: =D24+E24 | I24: =G24+H24 | J24: =D24+G24 | K24: =E24+H24 | L24: =J24+K24 | M24: =IF(C24=0,0,L24/C24*100)
A25: 4 | B25: =B8 | C25: =C8 | F25: =D25+E25 | I25: =G25+H25 | J25: =D25+G25 | K25: =E25+H25 | L25: =J25+K25 | M25: =IF(C25=0,0,L25/C25*100)
A26: 5 | B26: =B9 | C26: =C9 | F26: =D26+E26 | I26: =G26+H26 | J26: =D26+G26 | K26: =E26+H26 | L26: =J26+K26 | M26: =IF(C26=0,0,L26/C26*100)
A27: 6 | B27: =B10 | C27: =C10 | F27: =D27+E27 | I27: =G27+H27 | J27: =D27+G27 | K27: =E27+H27 | L27: =J27+K27 | M27: =IF(C27=0,0,L27/C27*100)
A28: 7 | B28: =B11 | C28: =C11 | F28: =D28+E28 | I28: =G28+H28 | J28: =D28+G28 | K28: =E28+H28 | L28: =J28+K28 | M28: =IF(C28=0,0,L28/C28*100)
A29: 8 | B29: =B12 | C29: =C12 | F29: =D29+E29 | I29: =G29+H29 | J29: =D29+G29 | K29: =E29+H29 | L29: =J29+K29 | M29: =IF(C29=0,0,L29/C29*100)
A30: 9 | B30: =B13 | C30: =C13 | F30: =D30+E30 | I30: =G30+H30 | J30: =D30+G30 | K30: =E30+H30 | L30: =J30+K30 | M30: =IF(C30=0,0,L30/C30*100)
A31: 10 | B31: =B14 | C31: =C14 | F31: =D31+E31 | I31: =G31+H31 | J31: =D31+G31 | K31: =E31+H31 | L31: =J31+K31 | M31: =IF(C31=0,0,L31/C31*100)
A32: 11 | B32: =B15 | C32: =C15 | F32: =D32+E32 | I32: =G32+H32 | J32: =D32+G32 | K32: =E32+H32 | L32: =J32+K32 | M32: =IF(C32=0,0,L32/C32*100)
A33: Total | B33: =SUM(B22:B32) | C33: =SUM(C22:C32) | D33: =SUM(D22:D32) | E33: =SUM(E22:E32) | F33: =D33+E33 | G33: =SUM(G22:G32) | H33: =SUM(H22:H32) | I33: =G33+H33 | J33: =D33+G33 | K33: =E33+H33 | L33: =J33+K33 | M33: =IF(C33=0,0,L33/C33*100)
A35: Day 2 - 2026-10-06 (Tue 20 Aswin 2083)
A36: Ward no. | B36: Total population | C36: JE target population | D36: Vaccinated | M36: Progress %
D37: Age 30-60 yrs | G37: Age 60 above | J37: Total | L37: Grand Total
D38: F | E38: M | F38: Total | G38: F | H38: M | I38: Total | J38: F | K38: M
A39: 1 | B39: =B5 | C39: =C5 | F39: =D39+E39 | I39: =G39+H39 | J39: =D39+G39 | K39: =E39+H39 | L39: =J39+K39 | M39: =IF(C39=0,0,L39/C39*100)
A40: 2 | B40: =B6 | C40: =C6 | F40: =D40+E40 | I40: =G40+H40 | J40: =D40+G40 | K40: =E40+H40 | L40: =J40+K40 | M40: =IF(C40=0,0,L40/C40*100)
A41: 3 | B41: =B7 | C41: =C7 | F41: =D41+E41 | I41: =G41+H41 | J41: =D41+G41 | K41: =E41+H41 | L41: =J41+K41 | M41: =IF(C41=0,0,L41/C41*100)
A42: 4 | B42: =B8 | C42: =C8 | F42: =D42+E42 | I42: =G42+H42 | J42: =D42+G42 | K42: =E42+H42 | L42: =J42+K42 | M42: =IF(C42=0,0,L42/C42*100)
...

Sheet Kankai Municipality
A1: Kankai Municipality - Campaign Total (5-19 Oct 2026)
A2: Ward no. | B2: Total population | C2: JE target population | D2: Vaccinated | M2: Progress %
D3: Age 30-60 yrs | G3: Age 60 above | J3: Total | L3: Grand Total
D4: F | E4: M | F4: Total | G4: F | H4: M | I4: Total | J4: F | K4: M
A5: 1 | B5: 5097 | C5: 2446.56 | D5: =D20+D35+D50+D65+D80+D95+D110+D125+D140+D155+D170+D185+D200+D215+D230 | E5: =E20+E35+E50+E65+E80+E95+E110+E125+E140+E155+E170+E185+E200+E215+E230 | F5: =D5+E5 | G5: =G20+G35+G50+G65+G80+G95+G110+G125+G140+G155+G170+G185+G200+G215+G230 | H5: =H20+H35+H50+H65+H80+H95+H110+H125+H140+H155+H170+H185+H200+H215+H230 | I5: =G5+H5 | J5: =D5+G5 | K5: =E5+H5 | L5: =J5+K5 | M5: =IF(C5=0,0,L5/C5*100)
A6: 2 | B6: 5126 | C6: 2460.48 | D6: =D21+D36+D51+D66+D81+D96+D111+D126+D141+D156+D171+D186+D201+D216+D231 | E6: =E21+E36+E51+E66+E81+E96+E111+E126+E141+E156+E171+E186+E201+E216+E231 | F6: =D6+E6 | G6: =G21+G36+G51+G66+G81+G96+G111+G126+G141+G156+G171+G186+G201+G216+G231 | H6: =H21+H36+H51+H66+H81+H96+H111+H126+H141+H156+H171+H186+H201+H216+H231 | I6: =G6+H6 | J6: =D6+G6 | K6: =E6+H6 | L6: =J6+K6 | M6: =IF(C6=0,0,L6/C6*100)
A7: 3 | B7: 13610 | C7: 6532.8 | D7: =D22+D37+D52+D67+D82+D97+D112+D127+D142+D157+D172+D187+D202+D217+D232 | E7: =E22+E37+E52+E67+E82+E97+E112+E127+E142+E157+E172+E187+E202+E217+E232 | F7: =D7+E7 | G7: =G22+G37+G52+G67+G82+G97+G112+G127+G142+G157+G172+G187+G202+G217+G232 | H7: =H22+H37+H52+H67+H82+H97+H112+H127+H142+H157+H172+H187+H202+H217+H232 | I7: =G7+H7 | J7: =D7+G7 | K7: =E7+H7 | L7: =J7+K7 | M7: =IF(C7=0,0,L7/C7*100)
A8: 4 | B8: 7634 | C8: 3664.32 | D8: =D23+D38+D53+D68+D83+D98+D113+D128+D143+D158+D173+D188+D203+D218+D233 | E8: =E23+E38+E53+E68+E83+E98+E113+E128+E143+E158+E173+E188+E203+E218+E233 | F8: =D8+E8 | G8: =G23+G38+G53+G68+G83+G98+G113+G128+G143+G158+G173+G188+G203+G218+G233 | H8: =H23+H38+H53+H68+H83+H98+H113+H128+H143+H158+H173+H188+H203+H218+H233 | I8: =G8+H8 | J8: =D8+G8 | K8: =E8+H8 | L8: =J8+K8 | M8: =IF(C8=0,0,L8/C8*100)
A9: 5 | B9: 6548 | C9: 3143.04 | D9: =D24+D39+D54+D69+D84+D99+D114+D129+D144+D159+D174+D189+D204+D219+D234 | E9: =E24+E39+E54+E69+E84+E99+E114+E129+E144+E159+E174+E189+E204+E219+E234 | F9: =D9+E9 | G9: =G24+G39+G54+G69+G84+G99+G114+G129+G144+G159+G174+G189+G204+G219+G234 | H9: =H24+H39+H54+H69+H84+H99+H114+H129+H144+H159+H174+H189+H204+H219+H234 | I9: =G9+H9 | J9: =D9+G9 | K9: =E9+H9 | L9: =J9+K9 | M9: =IF(C9=0,0,L9/C9*100)
A10: 6 | B10: 2725 | C10: 1308 | D10: =D25+D40+D55+D70+D85+D100+D115+D130+D145+D160+D175+D190+D205+D220+D235 | E10: =E25+E40+E55+E70+E85+E100+E115+E130+E145+E160+E175+E190+E205+E220+E235 | F10: =D10+E10 | G10: =G25+G40+G55+G70+G85+G100+G115+G130+G145+G160+G175+G190+G205+G220+G235 | H10: =H25+H40+H55+H70+H85+H100+H115+H130+H145+H160+H175+H190+H205+H220+H235 | I10: =G10+H10 | J10: =D10+G10 | K10: =E10+H10 | L10: =J10+K10 | M10: =IF(C10=0,0,L10/C10*100)
A11: 7 | B11: 4662 | C11: 2237.76 | D11: =D26+D41+D56+D71+D86+D101+D116+D131+D146+D161+D176+D191+D206+D221+D236 | E11: =E26+E41+E56+E71+E86+E101+E116+E131+E146+E161+E176+E191+E206+E221+E236 | F11: =D11+E11 | G11: =G26+G41+G56+G71+G86+G101+G116+G131+G146+G161+G176+G191+G206+G221+G236 | H11: =H26+H41+H56+H71+H86+H101+H116+H131+H146+H161+H176+H191+H206+H221+H236 | I11: =G11+H11 | J11: =D11+G11 | K11: =E11+H11 | L11: =J11+K11 | M11: =IF(C11=0,0,L11/C11*100)
A12: 8 | B12: 5552 | C12: 2664.96 | D12: =D27+D42+D57+D72+D87+D102+D117+D132+D147+D162+D177+D192+D207+D222+D237 | E12: =E27+E42+E57+E72+E87+E102+E117+E132+E147+E162+E177+E192+E207+E222+E237 | F12: =D12+E12 | G12: =G27+G42+G57+G72+G87+G102+G117+G132+G147+G162+G177+G192+G207+G222+G237 | H12: =H27+H42+H57+H72+H87+H102+H117+H132+H147+H162+H177+H192+H207+H222+H237 | I12: =G12+H12 | J12: =D12+G12 | K12: =E12+H12 | L12: =J12+K12 | M12: =IF(C12=0,0,L12/C12*100)
A13: 9 | B13: 3727 | C13: 1788.96 | D13: =D28+D43+D58+D73+D88+D103+D118+D133+D148+D163+D178+D193+D208+D223+D238 | E13: =E28+E43+E58+E73+E88+E103+E118+E133+E148+E163+E178+E193+E208+E223+E238 | F13: =D13+E13 | G13: =G28+G43+G58+G73+G88+G103+G118+G133+G148+G163+G178+G193+G208+G223+G238 | H13: =H28+H43+H58+H73+H88+H103+H118+H133+H148+H163+H178+H193+H208+H223+H238 | I13: =G13+H13 | J13: =D13+G13 | K13: =E13+H13 | L13: =J13+K13 | M13: =IF(C13=0,0,L13/C13*100)
A14: Total | B14: =SUM(B5:B13) | C14: =SUM(C5:C13) | D14: =SUM(D5:D13) | E14: =SUM(E5:E13) | F14: =D14+E14 | G14: =SUM(G5:G13) | H14: =SUM(H5:H13) | I14: =G14+H14 | J14: =D14+G14 | K14: =E14+H14 | L14: =J14+K14 | M14: =IF(C14=0,0,L14/C14*100)
A16: Day 1 - 2026-10-05 (Mon 19 Aswin 2083)
A17: Ward no. | B17: Total population | C17: JE target population | D17: Vaccinated | M17: Progress %
D18: Age 30-60 yrs | G18: Age 60 above | J18: Total | L18: Grand Total
D19: F | E19: M | F19: Total | G19: F | H19: M | I19: Total | J19: F | K19: M
A20: 1 | B20: =B5 | C20: =C5 | F20: =D20+E20 | I20: =G20+H20 | J20: =D20+G20 | K20: =E20+H20 | L20: =J20+K20 | M20: =IF(C20=0,0,L20/C20*100)
A21: 2 | B21: =B6 | C21: =C6 | F21: =D21+E21 | I21: =G21+H21 | J21: =D21+G21 | K21: =E21+H21 | L21: =J21+K21 | M21: =IF(C21=0,0,L21/C21*100)
A22: 3 | B22: =B7 | C22: =C7 | F22: =D22+E22 | I22: =G22+H22 | J22: =D22+G22 | K22: =E22+H22 | L22: =J22+K22 | M22: =IF(C22=0,0,L22/C22*100)
A23: 4 | B23: =B8 | C23: =C8 | F23: =D23+E23 | I23: =G23+H23 | J23: =D23+G23 | K23: =E23+H23 | L23: =J23+K23 | M23: =IF(C23=0,0,L23/C23*100)
A24: 5 | B24: =B9 | C24: =C9 | F24: =D24+E24 | I24: =G24+H24 | J24: =D24+G24 | K24: =E24+H24 | L24: =J24+K24 | M24: =IF(C24=0,0,L24/C24*100)
A25: 6 | B25: =B10 | C25: =C10 | F25: =D25+E25 | I25: =G25+H25 | J25: =D25+G25 | K25: =E25+H25 | L25: =J25+K25 | M25: =IF(C25=0,0,L25/C25*100)
A26: 7 | B26: =B11 | C26: =C11 | F26: =D26+E26 | I26: =G26+H26 | J26: =D26+G26 | K26: =E26+H26 | L26: =J26+K26 | M26: =IF(C26=0,0,L26/C26*100)
A27: 8 | B27: =B12 | C27: =C12 | F27: =D27+E27 | I27: =G27+H27 | J27: =D27+G27 | K27: =E27+H27 | L27: =J27+K27 | M27: =IF(C27=0,0,L27/C27*100)
A28: 9 | B28: =B13 | C28: =C13 | F28: =D28+E28 | I28: =G28+H28 | J28: =D28+G28 | K28: =E28+H28 | L28: =J28+K28 | M28: =IF(C28=0,0,L28/C28*100)
A29: Total | B29: =SUM(B20:B28) | C29: =SUM(C20:C28) | D29: =SUM(D20:D28) | E29: =SUM(E20:E28) | F29: =D29+E29 | G29: =SUM(G20:G28) | H29: =SUM(H20:H28) | I29: =G29+H29 | J29: =D29+G29 | K29: =E29+H29 | L29: =J29+K29 | M29: =IF(C29=0,0,L29/C29*100)
A31: Day 2 - 2026-10-06 (Tue 20 Aswin 2083)
A32: Ward no. | B32: Total population | C32: JE target population | D32: Vaccinated | M32: Progress %
D33: Age 30-60 yrs | G33: Age 60 above | J33: Total | L33: Grand Total
D34: F | E34: M | F34: Total | G34: F | H34: M | I34: Total | J34: F | K34: M
A35: 1 | B35: =B5 | C35: =C5 | F35: =D35+E35 | I35: =G35+H35 | J35: =D35+G35 | K35: =E35+H35 | L35: =J35+K35 | M35: =IF(C35=0,0,L35/C35*100)
A36: 2 | B36: =B6 | C36: =C6 | F36: =D36+E36 | I36: =G36+H36 | J36: =D36+G36 | K36: =E36+H36 | L36: =J36+K36 | M36: =IF(C36=0,0,L36/C36*100)
A37: 3 | B37: =B7 | C37: =C7 | F37: =D37+E37 | I37: =G37+H37 | J37: =D37+G37 | K37: =E37+H37 | L37: =J37+K37 | M37: =IF(C37=0,0,L37/C37*100)
A38: 4 | B38: =B8 | C38: =C8 | F38: =D38+E38 | I38: =G38+H38 | J38: =D38+G38 | K38: =E38+H38 | L38: =J38+K38 | M38: =IF(C38=0,0,L38/C38*100)
A39: 5 | B39: =B9 | C39: =C9 | F39: =D39+E39 | I39: =G39+H39 | J39: =D39+G39 | K39: =E39+H39 | L39: =J39+K39 | M39: =IF(C39=0,0,L39/C39*100)
A40: 6 | B40: =B10 | C40: =C10 | F40: =D40+E40 | I40: =G40+H40 | J40: =D40+G40 | K40: =E40+H40 | L40: =J40+K40 | M40: =IF(C40=0,0,L40/C40*100)
A41: 7 | B41: =B11 | C41: =C11 | F41: =D41+E41 | I41: =G41+H41 | J41: =D41+G41 | K41: =E41+H41 | L41: =J41+K41 | M41: =IF(C41=0,0,L41/C41*100)
A42: 8 | B42: =B12 | C42: =C12 | F42: =D42+E42 | I42: =G42+H42 | J42: =D42+G42 | K42: =E42+H42 | L42: =J42+K42 | M42: =IF(C42=0,0,L42/C42*100)
...

Sheet Shivasatakshi Municipality
A1: Shivasatakshi Municipality - Campaign Total (5-19 Oct 2026)
A2: Ward no. | B2: Total population | C2: JE target population | D2: Vaccinated | M2: Progress %
D3: Age 30-60 yrs | G3: Age 60 above | J3: Total | L3: Grand Total
D4: F | E4: M | F4: Total | G4: F | H4: M | I4: Total | J4: F | K4: M
A5: 1 | B5: 6369 | C5: 3057.12 | D5: =D22+D39+D56+D73+D90+D107+D124+D141+D158+D175+D192+D209+D226+D243+D260 | E5: =E22+E39+E56+E73+E90+E107+E124+E141+E158+E175+E192+E209+E226+E243+E260 | F5: =D5+E5 | G5: =G22+G39+G56+G73+G90+G107+G124+G141+G158+G175+G192+G209+G226+G243+G260 | H5: =H22+H39+H56+H73+H90+H107+H124+H141+H158+H175+H192+H209+H226+H243+H260 | I5: =G5+H5 | J5: =D5+G5 | K5: =E5+H5 | L5: =J5+K5 | M5: =IF(C5=0,0,L5/C5*100)
A6: 2 | B6: 6172 | C6: 2962.56 | D6: =D23+D40+D57+D74+D91+D108+D125+D142+D159+D176+D193+D210+D227+D244+D261 | E6: =E23+E40+E57+E74+E91+E108+E125+E142+E159+E176+E193+E210+E227+E244+E261 | F6: =D6+E6 | G6: =G23+G40+G57+G74+G91+G108+G125+G142+G159+G176+G193+G210+G227+G244+G261 | H6: =H23+H40+H57+H74+H91+H108+H125+H142+H159+H176+H193+H210+H227+H244+H261 | I6: =G6+H6 | J6: =D6+G6 | K6: =E6+H6 | L6: =J6+K6 | M6: =IF(C6=0,0,L6/C6*100)
A7: 3 | B7: 4635 | C7: 2224.8 | D7: =D24+D41+D58+D75+D92+D109+D126+D143+D160+D177+D194+D211+D228+D245+D262 | E7: =E24+E41+E58+E75+E92+E109+E126+E143+E160+E177+E194+E211+E228+E245+E262 | F7: =D7+E7 | G7: =G24+G41+G58+G75+G92+G109+G126+G143+G160+G177+G194+G211+G228+G245+G262 | H7: =H24+H41+H58+H75+H92+H109+H126+H143+H160+H177+H194+H211+H228+H245+H262 | I7: =G7+H7 | J7: =D7+G7 | K7: =E7+H7 | L7: =J7+K7 | M7: =IF(C7=0,0,L7/C7*100)
A8: 4 | B8: 6399 | C8: 3071.52 | D8: =D25+D42+D59+D76+D93+D110+D127+D144+D161+D178+D195+D212+D229+D246+D263 | E8: =E25+E42+E59+E76+E93+E110+E127+E144+E161+E178+E195+E212+E229+E246+E263 | F8: =D8+E8 | G8: =G25+G42+G59+G76+G93+G110+G127+G144+G161+G178+G195+G212+G229+G246+G263 | H8: =H25+H42+H59+H76+H93+H110+H127+H144+H161+H178+H195+H212+H229+H246+H263 | I8: =G8+H8 | J8: =D8+G8 | K8: =E8+H8 | L8: =J8+K8 | M8: =IF(C8=0,0,L8/C8*100)
A9: 5 | B9: 4767 | C9: 2288.16 | D9: =D26+D43+D60+D77+D94+D111+D128+D145+D162+D179+D196+D213+D230+D247+D264 | E9: =E26+E43+E60+E77+E94+E111+E128+E145+E162+E179+E196+E213+E230+E247+E264 | F9: =D9+E9 | G9: =G26+G43+G60+G77+G94+G111+G128+G145+G162+G179+G196+G213+G230+G247+G264 | H9: =H26+H43+H60+H77+H94+H111+H128+H145+H162+H179+H196+H213+H230+H247+H264 | I9: =G9+H9 | J9: =D9+G9 | K9: =E9+H9 | L9: =J9+K9 | M9: =IF(C9=0,0,L9/C9*100)
A10: 6 | B10: 6247 | C10: 2998.56 | D10: =D27+D44+D61+D78+D95+D112+D129+D146+D163+D180+D197+D214+D231+D248+D265 | E10: =E27+E44+E61+E78+E95+E112+E129+E146+E163+E180+E197+E214+E231+E248+E265 | F10: =D10+E10 | G10: =G27+G44+G61+G78+G95+G112+G129+G146+G163+G180+G197+G214+G231+G248+G265 | H10: =H27+H44+H61+H78+H95+H112+H129+H146+H163+H180+H197+H214+H231+H248+H265 | I10: =G10+H10 | J10: =D10+G10 | K10: =E10+H10 | L10: =J10+K10 | M10: =IF(C10=0,0,L10/C10*100)
A11: 7 | B11: 8247 | C11: 3958.56 | D11: =D28+D45+D62+D79+D96+D113+D130+D147+D164+D181+D198+D215+D232+D249+D266 | E11: =E28+E45+E62+E79+E96+E113+E130+E147+E164+E181+E198+E215+E232+E249+E266 | F11: =D11+E11 | G11: =G28+G45+G62+G79+G96+G113+G130+G147+G164+G181+G198+G215+G232+G249+G266 | H11: =H28+H45+H62+H79+H96+H113+H130+H147+H164+H181+H198+H215+H232+H249+H266 | I11: =G11+H11 | J11: =D11+G11 | K11: =E11+H11 | L11: =J11+K11 | M11: =IF(C11=0,0,L11/C11*100)
A12: 8 | B12: 9607 | C12: 4611.36 | D12: =D29+D46+D63+D80+D97+D114+D131+D148+D165+D182+D199+D216+D233+D250+D267 | E12: =E29+E46+E63+E80+E97+E114+E131+E148+E165+E182+E199+E216+E233+E250+E267 | F12: =D12+E12 | G12: =G29+G46+G63+G80+G97+G114+G131+G148+G165+G182+G199+G216+G233+G250+G267 | H12: =H29+H46+H63+H80+H97+H114+H131+H148+H165+H182+H199+H216+H233+H250+H267 | I12: =G12+H12 | J12: =D12+G12 | K12: =E12+H12 | L12: =J12+K12 | M12: =IF(C12=0,0,L12/C12*100)
A13: 9 | B13: 6800 | C13: 3264 | D13: =D30+D47+D64+D81+D98+D115+D132+D149+D166+D183+D200+D217+D234+D251+D268 | E13: =E30+E47+E64+E81+E98+E115+E132+E149+E166+E183+E200+E217+E234+E251+E268 | F13: =D13+E13 | G13: =G30+G47+G64+G81+G98+G115+G132+G149+G166+G183+G200+G217+G234+G251+G268 | H13: =H30+H47+H64+H81+H98+H115+H132+H149+H166+H183+H200+H217+H234+H251+H268 | I13: =G13+H13 | J13: =D13+G13 | K13: =E13+H13 | L13: =J13+K13 | M13: =IF(C13=0,0,L13/C13*100)
A14: 10 | B14: 7567 | C14: 3632.16 | D14: =D31+D48+D65+D82+D99+D116+D133+D150+D167+D184+D201+D218+D235+D252+D269 | E14: =E31+E48+E65+E82+E99+E116+E133+E150+E167+E184+E201+E218+E235+E252+E269 | F14: =D14+E14 | G14: =G31+G48+G65+G82+G99+G116+G133+G150+G167+G184+G201+G218+G235+G252+G269 | H14: =H31+H48+H65+H82+H99+H116+H133+H150+H167+H184+H201+H218+H235+H252+H269 | I14: =G14+H14 | J14: =D14+G14 | K14: =E14+H14 | L14: =J14+K14 | M14: =IF(C14=0,0,L14/C14*100)
A15: 11 | B15: 9230 | C15: 4430.4 | D15: =D32+D49+D66+D83+D100+D117+D134+D151+D168+D185+D202+D219+D236+D253+D270 | E15: =E32+E49+E66+E83+E100+E117+E134+E151+E168+E185+E202+E219+E236+E253+E270 | F15: =D15+E15 | G15: =G32+G49+G66+G83+G100+G117+G134+G151+G168+G185+G202+G219+G236+G253+G270 | H15: =H32+H49+H66+H83+H100+H117+H134+H151+H168+H185+H202+H219+H236+H253+H270 | I15: =G15+H15 | J15: =D15+G15 | K15: =E15+H15 | L15: =J15+K15 | M15: =IF(C15=0,0,L15/C15*100)
A16: Total | B16: =SUM(B5:B15) | C16: =SUM(C5:C15) | D16: =SUM(D5:D15) | E16: =SUM(E5:E15) | F16: =D16+E16 | G16: =SUM(G5:G15) | H16: =SUM(H5:H15) | I16: =G16+H16 | J16: =D16+G16 | K16: =E16+H16 | L16: =J16+K16 | M16: =IF(C16=0,0,L16/C16*100)
A18: Day 1 - 2026-10-05 (Mon 19 Aswin 2083)
A19: Ward no. | B19: Total population | C19: JE target population | D19: Vaccinated | M19: Progress %
D20: Age 30-60 yrs | G20: Age 60 above | J20: Total | L20: Grand Total
D21: F | E21: M | F21: Total | G21: F | H21: M | I21: Total | J21: F | K21: M
A22: 1 | B22: =B5 | C22: =C5 | F22: =D22+E22 | I22: =G22+H22 | J22: =D22+G22 | K22: =E22+H22 | L22: =J22+K22 | M22: =IF(C22=0,0,L22/C22*100)
A23: 2 | B23: =B6 | C23: =C6 | F23: =D23+E23 | I23: =G23+H23 | J23: =D23+G23 | K23: =E23+H23 | L23: =J23+K23 | M23: =IF(C23=0,0,L23/C23*100)
A24: 3 | B24: =B7 | C24: =C7 | F24: =D24+E24 | I24: =G24+H24 | J24: =D24+G24 | K24: =E24+H24 | L24: =J24+K24 | M24: =IF(C24=0,0,L24/C24*100)
A25: 4 | B25: =B8 | C25: =C8 | F25: =D25+E25 | I25: =G25+H25 | J25: =D25+G25 | K25: =E25+H25 | L25: =J25+K25 | M25: =IF(C25=0,0,L25/C25*100)
A26: 5 | B26: =B9 | C26: =C9 | F26: =D26+E26 | I26: =G26+H26 | J26: =D26+G26 | K26: =E26+H26 | L26: =J26+K26 | M26: =IF(C26=0,0,L26/C26*100)
A27: 6 | B27: =B10 | C27: =C10 | F27: =D27+E27 | I27: =G27+H27 | J27: =D27+G27 | K27: =E27+H27 | L27: =J27+K27 | M27: =IF(C27=0,0,L27/C27*100)
A28: 7 | B28: =B11 | C28: =C11 | F28: =D28+E28 | I28: =G28+H28 | J28: =D28+G28 | K28: =E28+H28 | L28: =J28+K28 | M28: =IF(C28=0,0,L28/C28*100)
A29: 8 | B29: =B12 | C29: =C12 | F29: =D29+E29 | I29: =G29+H29 | J29: =D29+G29 | K29: =E29+H29 | L29: =J29+K29 | M29: =IF(C29=0,0,L29/C29*100)
A30: 9 | B30: =B13 | C30: =C13 | F30: =D30+E30 | I30: =G30+H30 | J30: =D30+G30 | K30: =E30+H30 | L30: =J30+K30 | M30: =IF(C30=0,0,L30/C30*100)
A31: 10 | B31: =B14 | C31: =C14 | F31: =D31+E31 | I31: =G31+H31 | J31: =D31+G31 | K31: =E31+H31 | L31: =J31+K31 | M31: =IF(C31=0,0,L31/C31*100)
A32: 11 | B32: =B15 | C32: =C15 | F32: =D32+E32 | I32: =G32+H32 | J32: =D32+G32 | K32: =E32+H32 | L32: =J32+K32 | M32: =IF(C32=0,0,L32/C32*100)
A33: Total | B33: =SUM(B22:B32) | C33: =SUM(C22:C32) | D33: =SUM(D22:D32) | E33: =SUM(E22:E32) | F33: =D33+E33 | G33: =SUM(G22:G32) | H33: =SUM(H22:H32) | I33: =G33+H33 | J33: =D33+G33 | K33: =E33+H33 | L33: =J33+K33 | M33: =IF(C33=0,0,L33/C33*100)
A35: Day 2 - 2026-10-06 (Tue 20 Aswin 2083)
A36: Ward no. | B36: Total population | C36: JE target population | D36: Vaccinated | M36: Progress %
D37: Age 30-60 yrs | G37: Age 60 above | J37: Total | L37: Grand Total
D38: F | E38: M | F38: Total | G38: F | H38: M | I38: Total | J38: F | K38: M
A39: 1 | B39: =B5 | C39: =C5 | F39: =D39+E39 | I39: =G39+H39 | J39: =D39+G39 | K39: =E39+H39 | L39: =J39+K39 | M39: =IF(C39=0,0,L39/C39*100)
A40: 2 | B40: =B6 | C40: =C6 | F40: =D40+E40 | I40: =G40+H40 | J40: =D40+G40 | K40: =E40+H40 | L40: =J40+K40 | M40: =IF(C40=0,0,L40/C40*100)
A41: 3 | B41: =B7 | C41: =C7 | F41: =D41+E41 | I41: =G41+H41 | J41: =D41+G41 | K41: =E41+H41 | L41: =J41+K41 | M41: =IF(C41=0,0,L41/C41*100)
A42: 4 | B42: =B8 | C42: =C8 | F42: =D42+E42 | I42: =G42+H42 | J42: =D42+G42 | K42: =E42+H42 | L42: =J42+K42 | M42: =IF(C42=0,0,L42/C42*100)
...

Sheet Kamal Gaunpalika
A1: Kamal Gaunpalika - Campaign Total (5-19 Oct 2026)
A2: Ward no. | B2: Total population | C2: JE target population | D2: Vaccinated | M2: Progress %
D3: Age 30-60 yrs | G3: Age 60 above | J3: Total | L3: Grand Total
D4: F | E4: M | F4: Total | G4: F | H4: M | I4: Total | J4: F | K4: M
A5: 1 | B5: 6877 | C5: 3300.96 | D5: =D18+D31+D44+D57+D70+D83+D96+D109+D122+D135+D148+D161+D174+D187+D200 | E5: =E18+E31+E44+E57+E70+E83+E96+E109+E122+E135+E148+E161+E174+E187+E200 | F5: =D5+E5 | G5: =G18+G31+G44+G57+G70+G83+G96+G109+G122+G135+G148+G161+G174+G187+G200 | H5: =H18+H31+H44+H57+H70+H83+H96+H109+H122+H135+H148+H161+H174+H187+H200 | I5: =G5+H5 | J5: =D5+G5 | K5: =E5+H5 | L5: =J5+K5 | M5: =IF(C5=0,0,L5/C5*100)
A6: 2 | B6: 6807 | C6: 3267.36 | D6: =D19+D32+D45+D58+D71+D84+D97+D110+D123+D136+D149+D162+D175+D188+D201 | E6: =E19+E32+E45+E58+E71+E84+E97+E110+E123+E136+E149+E162+E175+E188+E201 | F6: =D6+E6 | G6: =G19+G32+G45+G58+G71+G84+G97+G110+G123+G136+G149+G162+G175+G188+G201 | H6: =H19+H32+H45+H58+H71+H84+H97+H110+H123+H136+H149+H162+H175+H188+H201 | I6: =G6+H6 | J6: =D6+G6 | K6: =E6+H6 | L6: =J6+K6 | M6: =IF(C6=0,0,L6/C6*100)
A7: 3 | B7: 6565 | C7: 3151.2 | D7: =D20+D33+D46+D59+D72+D85+D98+D111+D124+D137+D150+D163+D176+D189+D202 | E7: =E20+E33+E46+E59+E72+E85+E98+E111+E124+E137+E150+E163+E176+E189+E202 | F7: =D7+E7 | G7: =G20+G33+G46+G59+G72+G85+G98+G111+G124+G137+G150+G163+G176+G189+G202 | H7: =H20+H33+H46+H59+H72+H85+H98+H111+H124+H137+H150+H163+H176+H189+H202 | I7: =G7+H7 | J7: =D7+G7 | K7: =E7+H7 | L7: =J7+K7 | M7: =IF(C7=0,0,L7/C7*100)
A8: 4 | B8: 8179 | C8: 3925.92 | D8: =D21+D34+D47+D60+D73+D86+D99+D112+D125+D138+D151+D164+D177+D190+D203 | E8: =E21+E34+E47+E60+E73+E86+E99+E112+E125+E138+E151+E164+E177+E190+E203 | F8: =D8+E8 | G8: =G21+G34+G47+G60+G73+G86+G99+G112+G125+G138+G151+G164+G177+G190+G203 | H8: =H21+H34+H47+H60+H73+H86+H99+H112+H125+H138+H151+H164+H177+H190+H203 | I8: =G8+H8 | J8: =D8+G8 | K8: =E8+H8 | L8: =J8+K8 | M8: =IF(C8=0,0,L8/C8*100)
A9: 5 | B9: 11141 | C9: 5347.68 | D9: =D22+D35+D48+D61+D74+D87+D100+D113+D126+D139+D152+D165+D178+D191+D204 | E9: =E22+E35+E48+E61+E74+E87+E100+E113+E126+E139+E152+E165+E178+E191+E204 | F9: =D9+E9 | G9: =G22+G35+G48+G61+G74+G87+G100+G113+G126+G139+G152+G165+G178+G191+G204 | H9: =H22+H35+H48+H61+H74+H87+H100+H113+H126+H139+H152+H165+H178+H191+H204 | I9: =G9+H9 | J9: =D9+G9 | K9: =E9+H9 | L9: =J9+K9 | M9: =IF(C9=0,0,L9/C9*100)
A10: 6 | B10: 8092 | C10: 3884.16 | D10: =D23+D36+D49+D62+D75+D88+D101+D114+D127+D140+D153+D166+D179+D192+D205 | E10: =E23+E36+E49+E62+E75+E88+E101+E114+E127+E140+E153+E166+E179+E192+E205 | F10: =D10+E10 | G10: =G23+G36+G49+G62+G75+G88+G101+G114+G127+G140+G153+G166+G179+G192+G205 | H10: =H23+H36+H49+H62+H75+H88+H101+H114+H127+H140+H153+H166+H179+H192+H205 | I10: =G10+H10 | J10: =D10+G10 | K10: =E10+H10 | L10: =J10+K10 | M10: =IF(C10=0,0,L10/C10*100)
A11: 7 | B11: 7480 | C11: 3590.4 | D11: =D24+D37+D50+D63+D76+D89+D102+D115+D128+D141+D154+D167+D180+D193+D206 | E11: =E24+E37+E50+E63+E76+E89+E102+E115+E128+E141+E154+E167+E180+E193+E206 | F11: =D11+E11 | G11: =G24+G37+G50+G63+G76+G89+G102+G115+G128+G141+G154+G167+G180+G193+G206 | H11: =H24+H37+H50+H63+H76+H89+H102+H115+H128+H141+H154+H167+H180+H193+H206 | I11: =G11+H11 | J11: =D11+G11 | K11: =E11+H11 | L11: =J11+K11 | M11: =IF(C11=0,0,L11/C11*100)
A12: Total | B12: =SUM(B5:B11) | C12: =SUM(C5:C11) | D12: =SUM(D5:D11) | E12: =SUM(E5:E11) | F12: =D12+E12 | G12: =SUM(G5:G11) | H12: =SUM(H5:H11) | I12: =G12+H12 | J12: =D12+G12 | K12: =E12+H12 | L12: =J12+K12 | M12: =IF(C12=0,0,L12/C12*100)
A14: Day 1 - 2026-10-05 (Mon 19 Aswin 2083)
A15: Ward no. | B15: Total population | C15: JE target population | D15: Vaccinated | M15: Progress %
D16: Age 30-60 yrs | G16: Age 60 above | J16: Total | L16: Grand Total
D17: F | E17: M | F17: Total | G17: F | H17: M | I17: Total | J17: F | K17: M
A18: 1 | B18: =B5 | C18: =C5 | F18: =D18+E18 | I18: =G18+H18 | J18: =D18+G18 | K18: =E18+H18 | L18: =J18+K18 | M18: =IF(C18=0,0,L18/C18*100)
A19: 2 | B19: =B6 | C19: =C6 | F19: =D19+E19 | I19: =G19+H19 | J19: =D19+G19 | K19: =E19+H19 | L19: =J19+K19 | M19: =IF(C19=0,0,L19/C19*100)
A20: 3 | B20: =B7 | C20: =C7 | F20: =D20+E20 | I20: =G20+H20 | J20: =D20+G20 | K20: =E20+H20 | L20: =J20+K20 | M20: =IF(C20=0,0,L20/C20*100)
A21: 4 | B21: =B8 | C21: =C8 | F21: =D21+E21 | I21: =G21+H21 | J21: =D21+G21 | K21: =E21+H21 | L21: =J21+K21 | M21: =IF(C21=0,0,L21/C21*100)
A22: 5 | B22: =B9 | C22: =C9 | F22: =D22+E22 | I22: =G22+H22 | J22: =D22+G22 | K22: =E22+H22 | L22: =J22+K22 | M22: =IF(C22=0,0,L22/C22*100)
A23: 6 | B23: =B10 | C23: =C10 | F23: =D23+E23 | I23: =G23+H23 | J23: =D23+G23 | K23: =E23+H23 | L23: =J23+K23 | M23: =IF(C23=0,0,L23/C23*100)
A24: 7 | B24: =B11 | C24: =C11 | F24: =D24+E24 | I24: =G24+H24 | J24: =D24+G24 | K24: =E24+H24 | L24: =J24+K24 | M24: =IF(C24=0,0,L24/C24*100)
A25: Total | B25: =SUM(B18:B24) | C25: =SUM(C18:C24) | D25: =SUM(D18:D24) | E25: =SUM(E18:E24) | F25: =D25+E25 | G25: =SUM(G18:G24) | H25: =SUM(H18:H24) | I25: =G25+H25 | J25: =D25+G25 | K25: =E25+H25 | L25: =J25+K25 | M25: =IF(C25=0,0,L25/C25*100)
A27: Day 2 - 2026-10-06 (Tue 20 Aswin 2083)
A28: Ward no. | B28: Total population | C28: JE target population | D28: Vaccinated | M28: Progress %
D29: Age 30-60 yrs | G29: Age 60 above | J29: Total | L29: Grand Total
D30: F | E30: M | F30: Total | G30: F | H30: M | I30: Total | J30: F | K30: M
A31: 1 | B31: =B5 | C31: =C5 | F31: =D31+E31 | I31: =G31+H31 | J31: =D31+G31 | K31: =E31+H31 | L31: =J31+K31 | M31: =IF(C31=0,0,L31/C31*100)
A32: 2 | B32: =B6 | C32: =C6 | F32: =D32+E32 | I32: =G32+H32 | J32: =D32+G32 | K32: =E32+H32 | L32: =J32+K32 | M32: =IF(C32=0,0,L32/C32*100)
A33: 3 | B33: =B7 | C33: =C7 | F33: =D33+E33 | I33: =G33+H33 | J33: =D33+G33 | K33: =E33+H33 | L33: =J33+K33 | M33: =IF(C33=0,0,L33/C33*100)
A34: 4 | B34: =B8 | C34: =C8 | F34: =D34+E34 | I34: =G34+H34 | J34: =D34+G34 | K34: =E34+H34 | L34: =J34+K34 | M34: =IF(C34=0,0,L34/C34*100)
A35: 5 | B35: =B9 | C35: =C9 | F35: =D35+E35 | I35: =G35+H35 | J35: =D35+G35 | K35: =E35+H35 | L35: =J35+K35 | M35: =IF(C35=0,0,L35/C35*100)
A36: 6 | B36: =B10 | C36: =C10 | F36: =D36+E36 | I36: =G36+H36 | J36: =D36+G36 | K36: =E36+H36 | L36: =J36+K36 | M36: =IF(C36=0,0,L36/C36*100)
A37: 7 | B37: =B11 | C37: =C11 | F37: =D37+E37 | I37: =G37+H37 | J37: =D37+G37 | K37: =E37+H37 | L37: =J37+K37 | M37: =IF(C37=0,0,L37/C37*100)
A38: Total | B38: =SUM(B31:B37) | C38: =SUM(C31:C37) | D38: =SUM(D31:D37) | E38: =SUM(E31:E37) | F38: =D38+E38 | G38: =SUM(G31:G37) | H38: =SUM(H31:H37) | I38: =G38+H38 | J38: =D38+G38 | K38: =E38+H38 | L38: =J38+K38 | M38: =IF(C38=0,0,L38/C38*100)
A40: Day 3 - 2026-10-07 (Wed 21 Aswin 2083)
A41: Ward no. | B41: Total population | C41: JE target population | D41: Vaccinated | M41: Progress %
D42: Age 30-60 yrs | G42: Age 60 above | J42: Total | L42: Grand Total
D43: F | E43: M | F43: Total | G43: F | H43: M | I43: Total | J43: F | K43: M
...

Sheet Damak Municipality
A1: Damak Municipality - Campaign Total (5-19 Oct 2026)
A2: Ward no. | B2: Total population | C2: JE target population | D2: Vaccinated | M2: Progress %
D3: Age 30-60 yrs | G3: Age 60 above | J3: Total | L3: Grand Total
D4: F | E4: M | F4: Total | G4: F | H4: M | I4: Total | J4: F | K4: M
A5: 1 | B5: 14924 | C5: 7163.52 | D5: =D21+D37+D53+D69+D85+D101+D117+D133+D149+D165+D181+D197+D213+D229+D245 | E5: =E21+E37+E53+E69+E85+E101+E117+E133+E149+E165+E181+E197+E213+E229+E245 | F5: =D5+E5 | G5: =G21+G37+G53+G69+G85+G101+G117+G133+G149+G165+G181+G197+G213+G229+G245 | H5: =H21+H37+H53+H69+H85+H101+H117+H133+H149+H165+H181+H197+H213+H229+H245 | I5: =G5+H5 | J5: =D5+G5 | K5: =E5+H5 | L5: =J5+K5 | M5: =IF(C5=0,0,L5/C5*100)
A6: 2 | B6: 12529 | C6: 6013.92 | D6: =D22+D38+D54+D70+D86+D102+D118+D134+D150+D166+D182+D198+D214+D230+D246 | E6: =E22+E38+E54+E70+E86+E102+E118+E134+E150+E166+E182+E198+E214+E230+E246 | F6: =D6+E6 | G6: =G22+G38+G54+G70+G86+G102+G118+G134+G150+G166+G182+G198+G214+G230+G246 | H6: =H22+H38+H54+H70+H86+H102+H118+H134+H150+H166+H182+H198+H214+H230+H246 | I6: =G6+H6 | J6: =D6+G6 | K6: =E6+H6 | L6: =J6+K6 | M6: =IF(C6=0,0,L6/C6*100)
A7: 3 | B7: 11756 | C7: 5642.88 | D7: =D23+D39+D55+D71+D87+D103+D119+D135+D151+D167+D183+D199+D215+D231+D247 | E7: =E23+E39+E55+E71+E87+E103+E119+E135+E151+E167+E183+E199+E215+E231+E247 | F7: =D7+E7 | G7: =G23+G39+G55+G71+G87+G103+G119+G135+G151+G167+G183+G199+G215+G231+G247 | H7: =H23+H39+H55+H71+H87+H103+H119+H135+H151+H167+H183+H199+H215+H231+H247 | I7: =G7+H7 | J7: =D7+G7 | K7: =E7+H7 | L7: =J7+K7 | M7: =IF(C7=0,0,L7/C7*100)
A8: 4 | B8: 12078 | C8: 5797.44 | D8: =D24+D40+D56+D72+D88+D104+D120+D136+D152+D168+D184+D200+D216+D232+D248 | E8: =E24+E40+E56+E72+E88+E104+E120+E136+E152+E168+E184+E200+E216+E232+E248 | F8: =D8+E8 | G8: =G24+G40+G56+G72+G88+G104+G120+G136+G152+G168+G184+G200+G216+G232+G248 | H8: =H24+H40+H56+H72+H88+H104+H120+H136+H152+H168+H184+H200+H216+H232+H248 | I8: =G8+H8 | J8: =D8+G8 | K8: =E8+H8 | L8: =J8+K8 | M8: =IF(C8=0,0,L8/C8*100)
A9: 5 | B9: 16384 | C9: 7864.32 | D9: =D25+D41+D57+D73+D89+D105+D121+D137+D153+D169+D185+D201+D217+D233+D249 | E9: =E25+E41+E57+E73+E89+E105+E121+E137+E153+E169+E185+E201+E217+E233+E249 | F9: =D9+E9 | G9: =G25+G41+G57+G73+G89+G105+G121+G137+G153+G169+G185+G201+G217+G233+G249 | H9: =H25+H41+H57+H73+H89+H105+H121+H137+H153+H169+H185+H201+H217+H233+H249 | I9: =G9+H9 | J9: =D9+G9 | K9: =E9+H9 | L9: =J9+K9 | M9: =IF(C9=0,0,L9/C9*100)
A10: 6 | B10: 6847 | C10: 3286.56 | D10: =D26+D42+D58+D74+D90+D106+D122+D138+D154+D170+D186+D202+D218+D234+D250 | E10: =E26+E42+E58+E74+E90+E106+E122+E138+E154+E170+E186+E202+E218+E234+E250 | F10: =D10+E10 | G10: =G26+G42+G58+G74+G90+G106+G122+G138+G154+G170+G186+G202+G218+G234+G250 | H10: =H26+H42+H58+H74+H90+H106+H122+H138+H154+H170+H186+H202+H218+H234+H250 | I10: =G10+H10 | J10: =D10+G10 | K10: =E10+H10 | L10: =J10+K10 | M10: =IF(C10=0,0,L10/C10*100)
A11: 7 | B11: 7961 | C11: 3821.28 | D11: =D27+D43+D59+D75+D91+D107+D123+D139+D155+D171+D187+D203+D219+D235+D251 | E11: =E27+E43+E59+E75+E91+E107+E123+E139+E155+E171+E187+E203+E219+E235+E251 | F11: =D11+E11 | G11: =G27+G43+G59+G75+G91+G107+G123+G139+G155+G171+G187+G203+G219+G235+G251 | H11: =H27+H43+H59+H75+H91+H107+H123+H139+H155+H171+H187+H203+H219+H235+H251 | I11: =G11+H11 | J11: =D11+G11 | K11: =E11+H11 | L11: =J11+K11 | M11: =IF(C11=0,0,L11/C11*100)
A12: 8 | B12: 11478 | C12: 5509.44 | D12: =D28+D44+D60+D76+D92+D108+D124+D140+D156+D172+D188+D204+D220+D236+D252 | E12: =E28+E44+E60+E76+E92+E108+E124+E140+E156+E172+E188+E204+E220+E236+E252 | F12: =D12+E12 | G12: =G28+G44+G60+G76+G92+G108+G124+G140+G156+G172+G188+G204+G220+G236+G252 | H12: =H28+H44+H60+H76+H92+H108+H124+H140+H156+H172+H188+H204+H220+H236+H252 | I12: =G12+H12 | J12: =D12+G12 | K12: =E12+H12 | L12: =J12+K12 | M12: =IF(C12=0,0,L12/C12*100)
A13: 9 | B13: 15078 | C13: 7237.44 | D13: =D29+D45+D61+D77+D93+D109+D125+D141+D157+D173+D189+D205+D221+D237+D253 | E13: =E29+E45+E61+E77+E93+E109+E125+E141+E157+E173+E189+E205+E221+E237+E253 | F13: =D13+E13 | G13: =G29+G45+G61+G77+G93+G109+G125+G141+G157+G173+G189+G205+G221+G237+G253 | H13: =H29+H45+H61+H77+H93+H109+H125+H141+H157+H173+H189+H205+H221+H237+H253 | I13: =G13+H13 | J13: =D13+G13 | K13: =E13+H13 | L13: =J13+K13 | M13: =IF(C13=0,0,L13/C13*100)
A14: 10 | B14: 6266 | C14: 3007.68 | D14: =D30+D46+D62+D78+D94+D110+D126+D142+D158+D174+D190+D206+D222+D238+D254 | E14: =E30+E46+E62+E78+E94+E110+E126+E142+E158+E174+E190+E206+E222+E238+E254 | F14: =D14+E14 | G14: =G30+G46+G62+G78+G94+G110+G126+G142+G158+G174+G190+G206+G222+G238+G254 | H14: =H30+H46+H62+H78+H94+H110+H126+H142+H158+H174+H190+H206+H222+H238+H254 | I14: =G14+H14 | J14: =D14+G14 | K14: =E14+H14 | L14: =J14+K14 | M14: =IF(C14=0,0,L14/C14*100)
A15: Total | B15: =SUM(B5:B14) | C15: =SUM(C5:C14) | D15: =SUM(D5:D14) | E15: =SUM(E5:E14) | F15: =D15+E15 | G15: =SUM(G5:G14) | H15: =SUM(H5:H14) | I15: =G15+H15 | J15: =D15+G15 | K15: =E15+H15 | L15: =J15+K15 | M15: =IF(C15=0,0,L15/C15*100)
A17: Day 1 - 2026-10-05 (Mon 19 Aswin 2083)
A18: Ward no. | B18: Total population | C18: JE target population | D18: Vaccinated | M18: Progress %
D19: Age 30-60 yrs | G19: Age 60 above | J19: Total | L19: Grand Total
D20: F | E20: M | F20: Total | G20: F | H20: M | I20: Total | J20: F | K20: M
A21: 1 | B21: =B5 | C21: =C5 | F21: =D21+E21 | I21: =G21+H21 | J21: =D21+G21 | K21: =E21+H21 | L21: =J21+K21 | M21: =IF(C21=0,0,L21/C21*100)
A22: 2 | B22: =B6 | C22: =C6 | F22: =D22+E22 | I22: =G22+H22 | J22: =D22+G22 | K22: =E22+H22 | L22: =J22+K22 | M22: =IF(C22=0,0,L22/C22*100)
A23: 3 | B23: =B7 | C23: =C7 | F23: =D23+E23 | I23: =G23+H23 | J23: =D23+G23 | K23: =E23+H23 | L23: =J23+K23 | M23: =IF(C23=0,0,L23/C23*100)
A24: 4 | B24: =B8 | C24: =C8 | F24: =D24+E24 | I24: =G24+H24 | J24: =D24+G24 | K24: =E24+H24 | L24: =J24+K24 | M24: =IF(C24=0,0,L24/C24*100)
A25: 5 | B25: =B9 | C25: =C9 | F25: =D25+E25 | I25: =G25+H25 | J25: =D25+G25 | K25: =E25+H25 | L25: =J25+K25 | M25: =IF(C25=0,0,L25/C25*100)
A26: 6 | B26: =B10 | C26: =C10 | F26: =D26+E26 | I26: =G26+H26 | J26: =D26+G26 | K26: =E26+H26 | L26: =J26+K26 | M26: =IF(C26=0,0,L26/C26*100)
A27: 7 | B27: =B11 | C27: =C11 | F27: =D27+E27 | I27: =G27+H27 | J27: =D27+G27 | K27: =E27+H27 | L27: =J27+K27 | M27: =IF(C27=0,0,L27/C27*100)
A28: 8 | B28: =B12 | C28: =C12 | F28: =D28+E28 | I28: =G28+H28 | J28: =D28+G28 | K28: =E28+H28 | L28: =J28+K28 | M28: =IF(C28=0,0,L28/C28*100)
A29: 9 | B29: =B13 | C29: =C13 | F29: =D29+E29 | I29: =G29+H29 | J29: =D29+G29 | K29: =E29+H29 | L29: =J29+K29 | M29: =IF(C29=0,0,L29/C29*100)
A30: 10 | B30: =B14 | C30: =C14 | F30: =D30+E30 | I30: =G30+H30 | J30: =D30+G30 | K30: =E30+H30 | L30: =J30+K30 | M30: =IF(C30=0,0,L30/C30*100)
A31: Total | B31: =SUM(B21:B30) | C31: =SUM(C21:C30) | D31: =SUM(D21:D30) | E31: =SUM(E21:E30) | F31: =D31+E31 | G31: =SUM(G21:G30) | H31: =SUM(H21:H30) | I31: =G31+H31 | J31: =D31+G31 | K31: =E31+H31 | L31: =J31+K31 | M31: =IF(C31=0,0,L31/C31*100)
A33: Day 2 - 2026-10-06 (Tue 20 Aswin 2083)
A34: Ward no. | B34: Total population | C34: JE target population | D34: Vaccinated | M34: Progress %
D35: Age 30-60 yrs | G35: Age 60 above | J35: Total | L35: Grand Total
D36: F | E36: M | F36: Total | G36: F | H36: M | I36: Total | J36: F | K36: M
A37: 1 | B37: =B5 | C37: =C5 | F37: =D37+E37 | I37: =G37+H37 | J37: =D37+G37 | K37: =E37+H37 | L37: =J37+K37 | M37: =IF(C37=0,0,L37/C37*100)
A38: 2 | B38: =B6 | C38: =C6 | F38: =D38+E38 | I38: =G38+H38 | J38: =D38+G38 | K38: =E38+H38 | L38: =J38+K38 | M38: =IF(C38=0,0,L38/C38*100)
A39: 3 | B39: =B7 | C39: =C7 | F39: =D39+E39 | I39: =G39+H39 | J39: =D39+G39 | K39: =E39+H39 | L39: =J39+K39 | M39: =IF(C39=0,0,L39/C39*100)
A40: 4 | B40: =B8 | C40: =C8 | F40: =D40+E40 | I40: =G40+H40 | J40: =D40+G40 | K40: =E40+H40 | L40: =J40+K40 | M40: =IF(C40=0,0,L40/C40*100)
A41: 5 | B41: =B9 | C41: =C9 | F41: =D41+E41 | I41: =G41+H41 | J41: =D41+G41 | K41: =E41+H41 | L41: =J41+K41 | M41: =IF(C41=0,0,L41/C41*100)
A42: 6 | B42: =B10 | C42: =C10 | F42: =D42+E42 | I42: =G42+H42 | J42: =D42+G42 | K42: =E42+H42 | L42: =J42+K42 | M42: =IF(C42=0,0,L42/C42*100)
...

Sheet Gauradaha Municipality
A1: Gauradaha Municipality - Campaign Total (5-19 Oct 2026)
A2: Ward no. | B2: Total population | C2: JE target population | D2: Vaccinated | M2: Progress %
D3: Age 30-60 yrs | G3: Age 60 above | J3: Total | L3: Grand Total
D4: F | E4: M | F4: Total | G4: F | H4: M | I4: Total | J4: F | K4: M
A5: 1 | B5: 10136 | C5: 4865.28 | D5: =D20+D35+D50+D65+D80+D95+D110+D125+D140+D155+D170+D185+D200+D215+D230 | E5: =E20+E35+E50+E65+E80+E95+E110+E125+E140+E155+E170+E185+E200+E215+E230 | F5: =D5+E5 | G5: =G20+G35+G50+G65+G80+G95+G110+G125+G140+G155+G170+G185+G200+G215+G230 | H5: =H20+H35+H50+H65+H80+H95+H110+H125+H140+H155+H170+H185+H200+H215+H230 | I5: =G5+H5 | J5: =D5+G5 | K5: =E5+H5 | L5: =J5+K5 | M5: =IF(C5=0,0,L5/C5*100)
A6: 2 | B6: 5101 | C6: 2448.48 | D6: =D21+D36+D51+D66+D81+D96+D111+D126+D141+D156+D171+D186+D201+D216+D231 | E6: =E21+E36+E51+E66+E81+E96+E111+E126+E141+E156+E171+E186+E201+E216+E231 | F6: =D6+E6 | G6: =G21+G36+G51+G66+G81+G96+G111+G126+G141+G156+G171+G186+G201+G216+G231 | H6: =H21+H36+H51+H66+H81+H96+H111+H126+H141+H156+H171+H186+H201+H216+H231 | I6: =G6+H6 | J6: =D6+G6 | K6: =E6+H6 | L6: =J6+K6 | M6: =IF(C6=0,0,L6/C6*100)
A7: 3 | B7: 4836 | C7: 2321.28 | D7: =D22+D37+D52+D67+D82+D97+D112+D127+D142+D157+D172+D187+D202+D217+D232 | E7: =E22+E37+E52+E67+E82+E97+E112+E127+E142+E157+E172+E187+E202+E217+E232 | F7: =D7+E7 | G7: =G22+G37+G52+G67+G82+G97+G112+G127+G142+G157+G172+G187+G202+G217+G232 | H7: =H22+H37+H52+H67+H82+H97+H112+H127+H142+H157+H172+H187+H202+H217+H232 | I7: =G7+H7 | J7: =D7+G7 | K7: =E7+H7 | L7: =J7+K7 | M7: =IF(C7=0,0,L7/C7*100)
A8: 4 | B8: 7697 | C8: 3694.56 | D8: =D23+D38+D53+D68+D83+D98+D113+D128+D143+D158+D173+D188+D203+D218+D233 | E8: =E23+E38+E53+E68+E83+E98+E113+E128+E143+E158+E173+E188+E203+E218+E233 | F8: =D8+E8 | G8: =G23+G38+G53+G68+G83+G98+G113+G128+G143+G158+G173+G188+G203+G218+G233 | H8: =H23+H38+H53+H68+H83+H98+H113+H128+H143+H158+H173+H188+H203+H218+H233 | I8: =G8+H8 | J8: =D8+G8 | K8: =E8+H8 | L8: =J8+K8 | M8: =IF(C8=0,0,L8/C8*100)
A9: 5 | B9: 8418 | C9: 4040.64 | D9: =D24+D39+D54+D69+D84+D99+D114+D129+D144+D159+D174+D189+D204+D219+D234 | E9: =E24+E39+E54+E69+E84+E99+E114+E129+E144+E159+E174+E189+E204+E219+E234 | F9: =D9+E9 | G9: =G24+G39+G54+G69+G84+G99+G114+G129+G144+G159+G174+G189+G204+G219+G234 | H9: =H24+H39+H54+H69+H84+H99+H114+H129+H144+H159+H174+H189+H204+H219+H234 | I9: =G9+H9 | J9: =D9+G9 | K9: =E9+H9 | L9: =J9+K9 | M9: =IF(C9=0,0,L9/C9*100)
A10: 6 | B10: 6965 | C10: 3343.2 | D10: =D25+D40+D55+D70+D85+D100+D115+D130+D145+D160+D175+D190+D205+D220+D235 | E10: =E25+E40+E55+E70+E85+E100+E115+E130+E145+E160+E175+E190+E205+E220+E235 | F10: =D10+E10 | G10: =G25+G40+G55+G70+G85+G100+G115+G130+G145+G160+G175+G190+G205+G220+G235 | H10: =H25+H40+H55+H70+H85+H100+H115+H130+H145+H160+H175+H190+H205+H220+H235 | I10: =G10+H10 | J10: =D10+G10 | K10: =E10+H10 | L10: =J10+K10 | M10: =IF(C10=0,0,L10/C10*100)
